Traceback (most recent call last):
  File "/home/carleondel/memes-bot/memes-bot/src/daily_meme_bot.py", line 19, in <module>
    run_script('src/retrieve_daily_memes.py')
  File "/home/carleondel/memes-bot/memes-bot/src/daily_meme_bot.py", line 12, in run_script
    result = subprocess.run(['python', script_name], capture_output=True, text=True)
  File "/usr/lib/python3.10/subprocess.py", line 503, in run
    with Popen(*popenargs, **kwargs) as process:
  File "/usr/lib/python3.10/subprocess.py", line 971, in __init__
    self._execute_child(args, executable, preexec_fn, close_fds,
  File "/usr/lib/python3.10/subprocess.py", line 1863, in _execute_child
    raise child_exception_type(errno_num, err_msg, err_filename)
FileNotFoundError: [Errno 2] No such file or directory: 'python'
